#예외 발생시키기


try:
	x=int(input())
	
	if x%3!=0:
		raise Exception('3의 배수가 아닙니다')

	print(x)

except Exception as e:
	print('예외가 발생했습니다' , e)

5를 입력시

예외가 발생했습니다.  3의 배수가 아닙니다. <- 라고 출력이 됨.



def three_multiple():
	x=int(input())
	if x%3!=0:
		raise Exception('3의 배수가 아닙니다')
	print(x)

try:
	three_multiple()

except Exception as e:
	print('예외가 발생했습니다' , e)

5 입력시

예외가 발생했습니다.  3의 배수가 아닙니다. <- 라고 출력이 됨.
단 오류가 생김


#현재 예외를 다시 발생시키기


except 안에 raise를 사용하면 현재 예외를 다시 발생시킴

def three_multiple():
	try:
		x=int(input())
	if x%3!=0:
		raise Exception('3의 배수가 아닙니다')
	print(x)
	
	except Exception as e:
		print('three_multiple 함수에서 예외가 발생했습니다. ' ,  e)
		raise 

try: 
	three_multipla()

except Exception as e:
	print('스크립트 파일에서 예외가 발생했습니다' , e)

5를 입력시

three_multiple 함수에서 예외가 발생했습니다. 3의 배수가 아닙니다.
스크립트 파일에서 예외가 발생했습니다. 3의 배수가 아닙니다 <- 라고 출력이 됨













